{
 "cells": [
  {
   "cell_type": "code",
   "execution_count": null,
   "metadata": {},
   "outputs": [
    {
     "name": "stderr",
     "output_type": "stream",
     "text": [
      "Using TensorFlow backend.\n"
     ]
    },
    {
     "ename": "ImportError",
     "evalue": "DLL load failed: 找不到指定的模块。",
     "output_type": "error",
     "traceback": [
      "\u001b[1;31m---------------------------------------------------------------------------\u001b[0m",
      "\u001b[1;31mImportError\u001b[0m                               Traceback (most recent call last)",
      "\u001b[1;31mImportError\u001b[0m: DLL load failed: 找不到指定的模块。"
     ]
    },
    {
     "name": "stderr",
     "output_type": "stream",
     "text": [
      "ERROR:root:Internal Python error in the inspect module.\n",
      "Below is the traceback from this internal error.\n",
      "\n"
     ]
    },
    {
     "name": "stdout",
     "output_type": "stream",
     "text": [
      "Traceback (most recent call last):\n",
      "  File \"D:\\ANACONDA\\envs\\tensorflow\\lib\\site-packages\\IPython\\core\\interactiveshell.py\", line 1806, in showtraceback\n",
      "    stb = value._render_traceback_()\n",
      "AttributeError: 'SystemError' object has no attribute '_render_traceback_'\n",
      "\n",
      "During handling of the above exception, another exception occurred:\n",
      "\n",
      "Traceback (most recent call last):\n",
      "  File \"D:\\ANACONDA\\envs\\tensorflow\\lib\\site-packages\\IPython\\core\\ultratb.py\", line 1090, in get_records\n",
      "    return _fixed_getinnerframes(etb, number_of_lines_of_context, tb_offset)\n",
      "  File \"D:\\ANACONDA\\envs\\tensorflow\\lib\\site-packages\\IPython\\core\\ultratb.py\", line 311, in wrapped\n",
      "    return f(*args, **kwargs)\n",
      "  File \"D:\\ANACONDA\\envs\\tensorflow\\lib\\site-packages\\IPython\\core\\ultratb.py\", line 345, in _fixed_getinnerframes\n",
      "    records = fix_frame_records_filenames(inspect.getinnerframes(etb, context))\n",
      "  File \"D:\\ANACONDA\\envs\\tensorflow\\lib\\inspect.py\", line 1453, in getinnerframes\n",
      "    frameinfo = (tb.tb_frame,) + getframeinfo(tb, context)\n",
      "  File \"D:\\ANACONDA\\envs\\tensorflow\\lib\\inspect.py\", line 1410, in getframeinfo\n",
      "    filename = getsourcefile(frame) or getfile(frame)\n",
      "  File \"D:\\ANACONDA\\envs\\tensorflow\\lib\\inspect.py\", line 672, in getsourcefile\n",
      "    if getattr(getmodule(object, filename), '__loader__', None) is not None:\n",
      "  File \"D:\\ANACONDA\\envs\\tensorflow\\lib\\inspect.py\", line 709, in getmodule\n",
      "    if ismodule(module) and hasattr(module, '__file__'):\n",
      "  File \"D:\\ANACONDA\\envs\\tensorflow\\lib\\site-packages\\tensorflow\\__init__.py\", line 50, in __getattr__\n",
      "    module = self._load()\n",
      "  File \"D:\\ANACONDA\\envs\\tensorflow\\lib\\site-packages\\tensorflow\\__init__.py\", line 44, in _load\n",
      "    module = _importlib.import_module(self.__name__)\n",
      "  File \"D:\\ANACONDA\\envs\\tensorflow\\lib\\importlib\\__init__.py\", line 126, in import_module\n",
      "    return _bootstrap._gcd_import(name[level:], package, level)\n",
      "  File \"<frozen importlib._bootstrap>\", line 986, in _gcd_import\n",
      "  File \"<frozen importlib._bootstrap>\", line 969, in _find_and_load\n",
      "  File \"<frozen importlib._bootstrap>\", line 956, in _find_and_load_unlocked\n",
      "ImportError: No module named 'tensorflow_core.estimator'\n"
     ]
    },
    {
     "name": "stderr",
     "output_type": "stream",
     "text": [
      "Error in sys.excepthook:\n",
      "Traceback (most recent call last):\n",
      "  File \"D:\\ANACONDA\\envs\\tensorflow\\lib\\site-packages\\IPython\\core\\interactiveshell.py\", line 1806, in showtraceback\n",
      "    stb = value._render_traceback_()\n",
      "AttributeError: 'SystemError' object has no attribute '_render_traceback_'\n",
      "\n",
      "During handling of the above exception, another exception occurred:\n",
      "\n",
      "Traceback (most recent call last):\n",
      "  File \"D:\\ANACONDA\\envs\\tensorflow\\lib\\site-packages\\IPython\\core\\interactiveshell.py\", line 1809, in showtraceback\n",
      "    value, tb, tb_offset=tb_offset)\n",
      "  File \"D:\\ANACONDA\\envs\\tensorflow\\lib\\site-packages\\IPython\\core\\ultratb.py\", line 1371, in structured_traceback\n",
      "    self, etype, value, tb, tb_offset, number_of_lines_of_context)\n",
      "  File \"D:\\ANACONDA\\envs\\tensorflow\\lib\\site-packages\\IPython\\core\\ultratb.py\", line 1279, in structured_traceback\n",
      "    self, etype, value, tb, tb_offset, number_of_lines_of_context\n",
      "  File \"D:\\ANACONDA\\envs\\tensorflow\\lib\\site-packages\\IPython\\core\\ultratb.py\", line 1140, in structured_traceback\n",
      "    formatted_exceptions += self.prepare_chained_exception_message(evalue.__cause__)\n",
      "TypeError: Can't convert 'list' object to str implicitly\n",
      "\n",
      "Original exception was:\n",
      "ImportError: numpy.core.multiarray failed to import\n",
      "\n",
      "During handling of the above exception, another exception occurred:\n",
      "\n",
      "Traceback (most recent call last):\n",
      "  File \"<frozen importlib._bootstrap>\", line 968, in _find_and_load\n",
      "SystemError: PyEval_EvalFrameEx returned a result with an error set\n"
     ]
    },
    {
     "ename": "ImportError",
     "evalue": "numpy.core._multiarray_umath failed to import",
     "output_type": "error",
     "traceback": [
      "\u001b[1;31m---------------------------------------------------------------------------\u001b[0m",
      "\u001b[1;31mImportError\u001b[0m                               Traceback (most recent call last)",
      "\u001b[1;31mImportError\u001b[0m: numpy.core._multiarray_umath failed to import"
     ]
    },
    {
     "ename": "ImportError",
     "evalue": "numpy.core.umath failed to import",
     "output_type": "error",
     "traceback": [
      "\u001b[1;31m---------------------------------------------------------------------------\u001b[0m",
      "\u001b[1;31mImportError\u001b[0m                               Traceback (most recent call last)",
      "\u001b[1;31mImportError\u001b[0m: numpy.core.umath failed to import"
     ]
    }
   ],
   "source": [
    "from keras.datasets import imdb\n",
    "from keras.preprocessing import sequence\n",
    "\n",
    "max_features=10000\n",
    "maxlen = 500\n",
    "batch_size=32\n",
    "\n",
    "print('Loading data...')\n",
    "(input_train,y_train),(input_test,y_test) = imdb.load_data(path='/kaggle/input/imdb.npz',\n",
    "                                                           num_words=max_features)\n",
    "print(len(input_train),'train sequences')\n",
    "print(len(input_test),'test sequences')\n",
    "\n",
    "print('Pad sequences (samples x time)')\n",
    "input_train = sequence.pad_sequences(input_train,maxlen=maxlen)\n",
    "input_test = sequence.pad_sequences(input_test,maxlen=maxlen)\n",
    "print('input_train shape:',input_train.shape)\n",
    "print('input_test shape:',input_test.shape)\n"
   ]
  },
  {
   "cell_type": "code",
   "execution_count": null,
   "metadata": {
    "collapsed": true
   },
   "outputs": [],
   "source": []
  }
 ],
 "metadata": {
  "kernelspec": {
   "display_name": "Python [conda env:tensorflow]",
   "language": "python",
   "name": "conda-env-tensorflow-py"
  },
  "language_info": {
   "codemirror_mode": {
    "name": "ipython",
    "version": 3
   },
   "file_extension": ".py",
   "mimetype": "text/x-python",
   "name": "python",
   "nbconvert_exporter": "python",
   "pygments_lexer": "ipython3",
   "version": "3.5.2"
  }
 },
 "nbformat": 4,
 "nbformat_minor": 2
}
